<?xml version="1.0"?>
<robot name="mars_rover">
  
  <material name="white">
    <color rgba='1 1 1 0.5'/>
  </material>
  
  <material name='blue'>
    <color rgba='0 1 0 0.5'/>
  </material>

  <link name="base_link">
    <visual>
      <geometry>
        <box size="1.2 1.2 0.3"/>
      </geometry>
      <material name='white'/>
      <origin rpy="0 0 0" xyz="0 0 0"/>
    </visual>
    <collision>
      <origin rpy="0 0 0" xyz="0 0 0"/>
      <geometry>
        <box size="1.2 1.2 0.3"/>
      </geometry>
    </collision>
    <inertial>
      <origin rpy="0 0 0" xyz="0 0 0"/>
      <mass value ='40'/>
      <inertia ixx='5.1' ixy='0.0' ixz='0.0' iyy='5.1' iyz ='0.0' izz='9.6'/>
    </inertial>
  </link>
  
  <link name='block_fl'>
    <visual>
      <geometry>
        <box size='0.1 0.1 0.1'/>
      </geometry>
      <material name='blue'/>
    </visual>
    <collision>
      <geometry>
        <box size='0.1 0.1 0.1'/>
      </geometry>
    </collision>
    <inertial>
      <mass value='0.5'/>
      <inertia ixx='8.333e-04' ixy='0.0' ixz='0.0' iyy='8.333e-04' iyz='0.0' izz='8.333e-04'/>
    </inertial>
  </link>

  <joint name='base_to_flblock' type='continuous'>
    <parent link='base_link'/>
    <child link='block_fl'/>
    <axis xyz='0 0 1'/>
    <origin rpy="0 0 0" xyz='0.535 0.495 -0.2'/>
    <dynamics damping='0.5'/>
  </joint>

  <link name="front_left_wheel">
    <visual>
      <geometry>
        <cylinder length="0.13" radius='0.105'/>
      </geometry>
    </visual>
    <collision>
      <geometry>
        <cylinder length="0.13" radius='0.105'/>
      </geometry>
    </collision>
    <inertial>
      <mass value='2'/>
      <inertia ixx='0.02718' ixy='0.0' ixz='0.0' iyy='0.02718' iyz='0.0' izz='0.011025'/>
    </inertial>
  </link>

  <!-- <gazebo reference="front_left_wheel">
    <mu1>1.0</mu1>
    <mu2>1.0</mu2>
    <kp>100000</kp>
    <kd>10</kd>
  </gazebo> -->

  <joint name='blockfl_to_fl' type="continuous">
    <parent link='block_fl'/>
    <child link='front_left_wheel'/>
    <axis xyz='0 0 1'/>
    <origin rpy="1.57075 0 1.57075" xyz='0 0 -0.155'/>
    <dynamics damping='0.1'/>  
  </joint>

  <link name='block_fr'>
    <visual>
        <geometry>
            <box size='0.1 0.1 0.1'/>
        </geometry>
        <material name='blue'/>
    </visual>
    <collision>
      <geometry>
        <box size='0.1 0.1 0.1'/>
      </geometry>
    </collision>
    <inertial>
      <mass value='0.5'/>
      <inertia ixx='8.333e-04' ixy='0.0' ixz='0.0' iyy='8.333e-04' iyz='0.0' izz='8.333e-04'/>
    </inertial>
  </link>

  <joint name='base_to_frblock' type='continuous'>
    <parent link='base_link'/>
    <child link='block_fr'/>
    <axis xyz='0 0 1'/>
    <origin rpy="0 0 0" xyz='-0.535 0.495 -0.2'/>
    <dynamics damping='0.5'/>
  </joint>
    
  <link name="front_right_wheel">
    <visual>
      <geometry>
        <cylinder length="0.13" radius='0.105'/>
      </geometry>
    </visual>
    <collision>
      <geometry>
        <cylinder length="0.13" radius='0.105'/>
      </geometry>
    </collision>
    <inertial>
      <mass value='2'/>
      <inertia ixx='0.02718' ixy='0.0' ixz='0.0' iyy='0.02718' iyz='0.0' izz='0.011025'/>
    </inertial>
  </link>

    <!-- <gazebo reference="front_right_wheel">
    <mu1>1.0</mu1>
    <mu2>1.0</mu2>
    <kp>100000</kp>
    <kd>10</kd>
  </gazebo> -->

  <joint name='blockfr_to_fr' type="continuous">
    <parent link='block_fr'/>
    <child link='front_right_wheel'/>
    <axis xyz='0 0 1'/>
    <origin rpy="1.57075 0 1.57075" xyz='0 0 -0.155'/>
    <dynamics damping='0.5'/>
  </joint>

  <link name='block_bl'>
    <visual>
        <geometry>
            <box size='0.1 0.1 0.1'/>
        </geometry>
        <material name='blue'/>
    </visual>
    <collision>
      <geometry>
        <box size='0.1 0.1 0.1'/>
      </geometry>
    </collision>
    <inertial>
      <mass value='0.5'/>
      <inertia ixx='8.333e-04' ixy='0.0' ixz='0.0' iyy='8.333e-04' iyz='0.0' izz='8.333e-04'/>
    </inertial>
  </link>

  <joint name='base_to_blblock' type='continuous'>
    <parent link='base_link'/>
    <child link='block_bl'/>
    <axis xyz='0 0 1'/>
    <origin rpy="0 0 0" xyz='0.535 -0.495 -0.2'/>
    <dynamics damping='0.5'/>
  </joint>

  <link name="back_left_wheel">
    <visual>
      <geometry>
        <cylinder length="0.13" radius='0.105'/>
      </geometry>
    </visual>
    <collision>
      <geometry>
        <cylinder length="0.13" radius='0.105'/>
      </geometry>
    </collision>
    <inertial>
      <mass value='2'/>
      <inertia ixx='0.02718' ixy='0.0' ixz='0.0' iyy='0.02718' iyz='0.0' izz='0.011025'/>
    </inertial>
  </link>

  <!-- <gazebo reference="back_left_wheel">
    <mu1>1.0</mu1>
    <mu2>1.0</mu2>
    <kp>100000</kp>
    <kd>10</kd>
  </gazebo> -->

  <joint name='blockbl_to_bl' type="continuous">
    <parent link='block_bl'/>
    <child link='back_left_wheel'/>
    <axis xyz='0 0 1'/>
    <origin rpy="1.57075 0 1.57075" xyz='0 0 -0.155'/>
    <dynamics damping='0.5'/>
  </joint>

  <link name='block_br'>
    <visual>
        <geometry>
            <box size='0.1 0.1 0.1'/>
        </geometry>
        <material name='blue'/>
    </visual>
    <collision>
      <geometry>
        <box size='0.1 0.1 0.1'/>
      </geometry>
    </collision>
    <inertial>
      <mass value='0.5'/>
      <inertia ixx='8.333e-04' ixy='0.0' ixz='0.0' iyy='8.333e-04' iyz='0.0' izz='8.333e-04'/>
    </inertial>
  </link>

  <joint name='base_to_brblock' type='continuous'>
    <parent link='base_link'/>
    <child link='block_br'/>
    <axis xyz='0 0 1'/>
    <origin rpy="0 0 0" xyz='-0.535 -0.495 -0.2'/>
    <dynamics damping='0.5'/>
  </joint>

  <link name="back_right_wheel">
    <visual>
      <geometry>
        <cylinder length="0.13" radius='0.105'/>
      </geometry>
    </visual>
    <collision>
      <geometry>
        <cylinder length="0.13" radius='0.105'/>
      </geometry>
    </collision>
    <inertial>
      <mass value='2'/>
      <inertia ixx='0.02718' ixy='0.0' ixz='0.0' iyy='0.02718' iyz='0.0' izz='0.011025'/>
    </inertial>
  </link>

  <!-- <gazebo reference="back_right_wheel">
    <mu1>1.0</mu1>
    <mu2>1.0</mu2>
    <kp>100000</kp>
    <kd>10</kd>
  </gazebo> -->

  <joint name='blockbr_to_br' type="continuous">
    <parent link='block_br'/>
    <child link='back_right_wheel'/>
    <axis xyz='0 0 1'/>
    <origin rpy="1.57075 0 1.57075" xyz='0 0 -0.155'/>
    <dynamics damping='0.5'/>
  </joint>

  <ros2_control name="GazeboSystem" type="system">
    <hardware>
      <plugin>gazebo_ros2_control/GazeboSystem</plugin>
    </hardware> 
    <joint name="blockfl_to_fl">
      <command_interface name="velocity"/>
      <state_interface name="position"/>
      <state_interface name="velocity"/>
    </joint>
  </ros2_control>
    
    <!--Steering joints (for the blocks that rotate)
    --> 

<!-- DO NOT TOUCH THIS PART NO IDEA WHY IT IS WORKING NOW -->

  <gazebo>
    <plugin name='gazebo_ros2_control' filename='libgazebo_ros2_control.so'>
      <robot_param>robot_description</robot_param>
      <robot_param_node>robot_state_publisher</robot_param_node>
      <parameters>/home/yash/steer_ws/src/swerve-steer/config/joint_controller.yaml</parameters>
    </plugin>
  </gazebo>
  
</robot>
